Workbook

Sheet Mode d'emploi
A1: Mode d'emploi du journal
A3: CODE COULEUR
A4: Cellule JAUNE, texte bleu = à remplir par vous (souvent un menu déroulant).
A5: Cellule blanche, texte noir = calcul automatique : ne pas modifier.
A6: Texte vert = valeur reprise d'une autre feuille.
A8: LES FEUILLES
A9: Checklist : à remplir AVANT chaque trade. Verdict automatique + calculateur de lots.
A10: Journal : une ligne par trade (300 lignes prêtes). Score /7 et qualité A+ / B / C calculés seuls.
A11: Tableau de bord : taux de réussite, TP1 %, espérance, drawdown, discipline, et résultats par session, marché, liquidité, émotion, erreur, jour.
A12: Revue hebdo : bilan chiffré de chaque semaine + vos conclusions + graphique des R par semaine.
A13: Paramètres : capital, risque, objectifs et listes des menus déroulants. À régler UNE fois au début.
A15: ROUTINE
... A32: EXEMPLE DE LIGNE BIEN REMPLIE (à reproduire dans le Journal)
A33: Date | B33: Heure | C33: Marché | D33: TF | E33: Session | F33: Sens | G33: Biais | H33: Zone | I33: Liquidité | J33: MSS | K33: FVG | L33: Zone entrée | M33: Annonce | N33: Entrée | O33: Stop | P33: TP2 | Q33: Risque % | R33: Résultat | S33: Règles | T33: Émotion | U33: Erreur | V33: Leçon
A34: 29/09/2026 | B34: 08:45 | C34: XAUUSD | D34: M15 | E34: Londres | F34: Achat | G34: Haussier | H34: Discount | I34: AS L | J34: CHoCH | K34: Oui | L34: FVG | M34: Non | N34: 3812.4 | O34: 3806.1 | P34: 3831.2 | Q34: 0,50 % | R34: TP2 | S34: Oui | T34: Calme | U34: Aucune | V34: Sweep de l'Asie à l'ouverture de Londres, entrée au CE du FVG : patience payante.
A35: Avec ces valeurs : score 7/7 (A+), TP1 = 3818,70, risque 6,30 points, R:R vers TP2 ≈ 3,0 → résultat TP2 = 0,5 × 1 + 0,5 × 3,0 = +2,0 R, soit +1,0 % du compte.

Sheet Checklist
A1: Checklist avant chaque trade
A2: À remplir AVANT de placer l'ordre. Répondez Oui / Non dans les cellules jaunes.
A4: Critère | B4: Réponse
A5: 1. Le biais H4 (dernier BOS) va dans le sens de mon trade
A6: 2. Achat en DISCOUNT / vente en PREMIUM (milieu du range H4)
A7: 3. Une liquidité a été balayée (PDH, PDL, AS H/L, EQH/EQL, BSL/SSL) : mèche au-delà, clôture en retour
A8: 4. MSS (CHoCH ou BOS interne) dans le sens du trade, en clôture
A9: 5. Le déplacement a laissé un FVG valide et NON mitigé (1er retour du prix)
A10: 6. Je suis dans une killzone : Londres ou New York
A11: 7. Pas d'annonce majeure (NFP, CPI, FOMC, taux) dans les 30 minutes
A13: Score | B13: =COUNTIF(B5:B11,"Oui")&" / 7" -> 0 / 7
A14: Trades déjà pris aujourd'hui | B14: =COUNTIF(Journal!$B$5:$B$304,TODAY()) -> 0
A15: R perdus aujourd'hui | B15: =-SUMIFS(Journal!$AA$5:$AA$304,Journal!$B$5:$B$304,TODAY(),Journal!$AA$5:$AA$304,"<0") -> 0
A17: VERDICT | B17: =IF(B14>=Paramètres!B10,"✘ PAS DE TRADE : quota du jour atteint",IF(B15>=Paramètres!B11,"✘ PAS DE TRADE : perte max. du jour atteinte",IF(COUNTIF(B5:B11,"Oui")=7,"✔ TRADE AUTORISÉ (setup A+)",IF(COUNTBLANK(B5:B11)>0,"… Répondez aux 7 questions","✘ PAS DE TRADE : il manque "&(7-COUNTIF(B5:B11,"Oui"))&" critère(s)")))) -> … Répondez aux 7 questions
A20: Calculateur de taille de position
A21: Capital du compte ($) | B21: =Paramètres!B4*(1+SUM(Journal!$AB$5:$AB$304)) -> 1000
A22: Risque (%) | B22: =Paramètres!B5 -> 0.005 | C22: Pré-rempli depuis Paramètres ; modifiable.
A23: Prix d'entrée
A24: Stop loss
A25: Taille d'un contrat (1 lot) | B25: 100 | C25: XAUUSD = 100 (onces) · EURUSD, GBPUSD = 100 000 · indices : voir la fiche du symbole chez votre courtier.
A26: Montant risqué ($) | B26: =B21*B22 -> 5
A27: Distance entrée - stop | B27: =IF(OR(B23="",B24=""),"",ABS(B23-B24))
A28: Taille de position (lots) | B28: =IF(OR(B27="",N(B27)=0),"",ROUNDDOWN(B26/(B27*B25),2)) | C28: Valable pour un compte en $ et un actif coté en $ (XAUUSD, EURUSD, GBPUSD, US30, NAS100). Pour USDJPY ou un compte dans une autre devise : vérifiez avec le calculateur de votre courtier.
A29: TP1 (1R) | B29: =IF(B27="","",B23+(B23-B24)*Paramètres!B6)
A30: TP2 minimum (2R) | B30: =IF(B27="","",B23+(B23-B24)*2)

Sheet Journal
A1: Journal de trading — Koss Smart Pro
A2: Une ligne par trade. Remplissez les cellules JAUNES (menus déroulants) ; les cellules blanches se calculent seules. Voir la feuille « Mode d'emploi ».
A3: CONTEXTE | E3: MARCHÉ | I3: CHECKLIST SMC (score auto /7) | R3: EXÉCUTION | Y3: RÉSULTAT | AD3: PSYCHOLOGIE ET LEÇON | AI3: CALCULS AUTOMATIQUES
A4: N° | B4: Date | C4: Jour | D4: Heure (Douala) | E4: Marché | F4: TF entrée | G4: Session | H4: Sens | I4: Biais HTF | J4: Discount / Premium | K4: Liquidité prise (sweep) | L4: MSS | M4: FVG valide non mitigé | N4: Zone d'entrée | O4: Annonce < 30 min | P4: Score /7 | Q4: Qualité | R4: Prix d'entrée | S4: Stop loss | T4: TP1 (auto) | U4: TP2 (liquidité visée) | V4: Risque (points) | W4: R:R vers TP2 | X4: Risque % (vide = défaut) | Y4: Résultat | Z4: R si sortie manuelle | AA4: R réalisé | AB4: Résultat % compte | AC4: Capital ($) | AD4: Règles respectées | AE4: Émotion | AF4: Erreur principale | AG4: Lien capture d'écran | AH4: Leçon / remarque | AI4: Cumul R | AJ4: Plus haut du cumul | AK4: Drawdown (R) | AL4: Série de pertes | AM4: Semaine du
A5: =IF(B5="","",ROW()-4) | C5: =IF(B5="","",CHOOSE(WEEKDAY(B5,2),"Lundi","Mardi","Mercredi","Jeudi","Vendredi","Samedi","Dimanche")) | P5: =IF(B5="","",OR(AND(H5="Achat",I5="Haussier"),AND(H5="Vente",I5="Baissier"))*1+OR(AND(H5="Achat",J5="Discount"),AND(H5="Vente",J5="Premium"))*1+AND(K5<>"",K5<>"Aucune")*1+OR(L5="CHoCH",L5="BOS")*1+(M5="Oui")*1+OR(G5="Londres",G5="New York")*1+(O5="Non")*1) | Q5: =IF(P5="","",IF(P5=7,"A+",IF(P5>=5,"B","C"))) | T5: =IF(OR(R5="",S5=""),"",R5+(R5-S5)*Paramètres!$B$6) | V5: =IF(OR(R5="",S5=""),"",ABS(R5-S5)) | W5: =IF(OR(U5="",V5="",N(V5)=0),"",ABS(U5-R5)/V5) | AA5: =IF(Y5="","",IF(Y5="Stop",-1,IF(Y5="BE",0,IF(Y5="TP1 + BE",Paramètres!$B$7*Paramètres!$B$6,IF(Y5="TP1 (100 %)",Paramètres!$B$6,IF(Y5="TP2",Paramètres!$B$7*Paramètres!$B$6+(1-Paramètres!$B$7)*N(W5),IF(Y5="Sortie manuelle",N(Z5),""))))))) | AB5: =IF(AA5="","",AA5*IF(X5="",Paramètres!$B$5,X5)) | AC5: =IF(AB5="","",Paramètres!$B$4*(1+SUM(AB$5:AB5))) | AI5: =IF(AA5="","",SUM(AA$5:AA5)) | AJ5: =IF(AI5="","",MAX(AI5,0)) | AK5: =IF(AI5="","",AI5-AJ5) | AL5: =IF(AA5="","",IF(AA5<0,1,0)) | AM5: =IF(B5="","",B5-WEEKDAY(B5,2)+1)
A6: =IF(B6="","",ROW()-4) | C6: =IF(B6="","",CHOOSE(WEEKDAY(B6,2),"Lundi","Mardi","Mercredi","Jeudi","Vendredi","Samedi","Dimanche")) | P6: =IF(B6="","",OR(AND(H6="Achat",I6="Haussier"),AND(H6="Vente",I6="Baissier"))*1+OR(AND(H6="Achat",J6="Discount"),AND(H6="Vente",J6="Premium"))*1+AND(K6<>"",K6<>"Aucune")*1+OR(L6="CHoCH",L6="BOS")*1+(M6="Oui")*1+OR(G6="Londres",G6="New York")*1+(O6="Non")*1) | Q6: =IF(P6="","",IF(P6=7,"A+",IF(P6>=5,"B","C"))) | T6: =IF(OR(R6="",S6=""),"",R6+(R6-S6)*Paramètres!$B$6) | V6: =IF(OR(R6="",S6=""),"",ABS(R6-S6)) | W6: =IF(OR(U6="",V6="",N(V6)=0),"",ABS(U6-R6)/V6) | AA6: =IF(Y6="","",IF(Y6="Stop",-1,IF(Y6="BE",0,IF(Y6="TP1 + BE",Paramètres!$B$7*Paramètres!$B$6,IF(Y6="TP1 (100 %)",Paramètres!$B$6,IF(Y6="TP2",Paramètres!$B$7*Paramètres!$B$6+(1-Paramètres!$B$7)*N(W6),IF(Y6="Sortie manuelle",N(Z6),""))))))) | AB6: =IF(AA6="","",AA6*IF(X6="",Paramètres!$B$5,X6)) | AC6: =IF(AB6="","",Paramètres!$B$4*(1+SUM(AB$5:AB6))) | AI6: =IF(AA6="","",SUM(AA$5:AA6)) | AJ6: =IF(AI6="","",MAX(AI6,MAX(AJ$5:AJ5),0)) | AK6: =IF(AI6="","",AI6-AJ6) | AL6: =IF(AA6="","",IF(AA6<0,N(AL5)+1,0)) | AM6: =IF(B6="","",B6-WEEKDAY(B6,2)+1)
A7: =IF(B7="","",ROW()-4) | C7: =IF(B7="","",CHOOSE(WEEKDAY(B7,2),"Lundi","Mardi","Mercredi","Jeudi","Vendredi","Samedi","Dimanche")) | P7: =IF(B7="","",OR(AND(H7="Achat",I7="Haussier"),AND(H7="Vente",I7="Baissier"))*1+OR(AND(H7="Achat",J7="Discount"),AND(H7="Vente",J7="Premium"))*1+AND(K7<>"",K7<>"Aucune")*1+OR(L7="CHoCH",L7="BOS")*1+(M7="Oui")*1+OR(G7="Londres",G7="New York")*1+(O7="Non")*1) | Q7: =IF(P7="","",IF(P7=7,"A+",IF(P7>=5,"B","C"))) | T7: =IF(OR(R7="",S7=""),"",R7+(R7-S7)*Paramètres!$B$6) | V7: =IF(OR(R7="",S7=""),"",ABS(R7-S7)) | W7: =IF(OR(U7="",V7="",N(V7)=0),"",ABS(U7-R7)/V7) | AA7: =IF(Y7="","",IF(Y7="Stop",-1,IF(Y7="BE",0,IF(Y7="TP1 + BE",Paramètres!$B$7*Paramètres!$B$6,IF(Y7="TP1 (100 %)",Paramètres!$B$6,IF(Y7="TP2",Paramètres!$B$7*Paramètres!$B$6+(1-Paramètres!$B$7)*N(W7),IF(Y7="Sortie manuelle",N(Z7),""))))))) | AB7: =IF(AA7="","",AA7*IF(X7="",Paramètres!$B$5,X7)) | AC7: =IF(AB7="","",Paramètres!$B$4*(1+SUM(AB$5:AB7))) | AI7: =IF(AA7="","",SUM(AA$5:AA7)) | AJ7: =IF(AI7="","",MAX(AI7,MAX(AJ$5:AJ6),0)) | AK7: =IF(AI7="","",AI7-AJ7) | AL7: =IF(AA7="","",IF(AA7<0,N(AL6)+1,0)) | AM7: =IF(B7="","",B7-WEEKDAY(B7,2)+1)
A8: =IF(B8="","",ROW()-4) | C8: =IF(B8="","",CHOOSE(WEEKDAY(B8,2),"Lundi","Mardi","Mercredi","Jeudi","Vendredi","Samedi","Dimanche")) | P8: =IF(B8="","",OR(AND(H8="Achat",I8="Haussier"),AND(H8="Vente",I8="Baissier"))*1+OR(AND(H8="Achat",J8="Discount"),AND(H8="Vente",J8="Premium"))*1+AND(K8<>"",K8<>"Aucune")*1+OR(L8="CHoCH",L8="BOS")*1+(M8="Oui")*1+OR(G8="Londres",G8="New York")*1+(O8="Non")*1) | Q8: =IF(P8="","",IF(P8=7,"A+",IF(P8>=5,"B","C"))) | T8: =IF(OR(R8="",S8=""),"",R8+(R8-S8)*Paramètres!$B$6) | V8: =IF(OR(R8="",S8=""),"",ABS(R8-S8)) | W8: =IF(OR(U8="",V8="",N(V8)=0),"",ABS(U8-R8)/V8) | AA8: =IF(Y8="","",IF(Y8="Stop",-1,IF(Y8="BE",0,IF(Y8="TP1 + BE",Paramètres!$B$7*Paramètres!$B$6,IF(Y8="TP1 (100 %)",Paramètres!$B$6,IF(Y8="TP2",Paramètres!$B$7*Paramètres!$B$6+(1-Paramètres!$B$7)*N(W8),IF(Y8="Sortie manuelle",N(Z8),""))))))) | AB8: =IF(AA8="","",AA8*IF(X8="",Paramètres!$B$5,X8)) | AC8: =IF(AB8="","",Paramètres!$B$4*(1+SUM(AB$5:AB8))) | AI8: =IF(AA8="","",SUM(AA$5:AA8)) | AJ8: =IF(AI8="","",MAX(AI8,MAX(AJ$5:AJ7),0)) | AK8: =IF(AI8="","",AI8-AJ8) | AL8: =IF(AA8="","",IF(AA8<0,N(AL7)+1,0)) | AM8: =IF(B8="","",B8-WEEKDAY(B8,2)+1)
A9: =IF(B9="","",ROW()-4) | C9: =IF(B9="","",CHOOSE(WEEKDAY(B9,2),"Lundi","Mardi","Mercredi","Jeudi","Vendredi","Samedi","Dimanche")) | P9: =IF(B9="","",OR(AND(H9="Achat",I9="Haussier"),AND(H9="Vente",I9="Baissier"))*1+OR(AND(H9="Achat",J9="Discount"),AND(H9="Vente",J9="Premium"))*1+AND(K9<>"",K9<>"Aucune")*1+OR(L9="CHoCH",L9="BOS")*1+(M9="Oui")*1+OR(G9="Londres",G9="New York")*1+(O9="Non")*1) | Q9: =IF(P9="","",IF(P9=7,"A+",IF(P9>=5,"B","C"))) | T9: =IF(OR(R9="",S9=""),"",R9+(R9-S9)*Paramètres!$B$6) | V9: =IF(OR(R9="",S9=""),"",ABS(R9-S9)) | W9: =IF(OR(U9="",V9="",N(V9)=0),"",ABS(U9-R9)/V9) | AA9: =IF(Y9="","",IF(Y9="Stop",-1,IF(Y9="BE",0,IF(Y9="TP1 + BE",Paramètres!$B$7*Paramètres!$B$6,IF(Y9="TP1 (100 %)",Paramètres!$B$6,IF(Y9="TP2",Paramètres!$B$7*Paramètres!$B$6+(1-Paramètres!$B$7)*N(W9),IF(Y9="Sortie manuelle",N(Z9),""))))))) | AB9: =IF(AA9="","",AA9*IF(X9="",Paramètres!$B$5,X9)) | AC9: =IF(AB9="","",Paramètres!$B$4*(1+SUM(AB$5:AB9))) | AI9: =IF(AA9="","",SUM(AA$5:AA9)) | AJ9: =IF(AI9="","",MAX(AI9,MAX(AJ$5:AJ8),0)) | AK9: =IF(AI9="","",AI9-AJ9) | AL9: =IF(AA9="","",IF(AA9<0,N(AL8)+1,0)) | AM9: =IF(B9="","",B9-WEEKDAY(B9,2)+1)
A10: =IF(B10="","",ROW()-4) | C10: =IF(B10="","",CHOOSE(WEEKDAY(B10,2),"Lundi","Mardi","Mercredi","Jeudi","Vendredi","Samedi","Dimanche")) | P10: =IF(B10="","",OR(AND(H10="Achat",I10="Haussier"),AND(H10="Vente",I10="Baissier"))*1+OR(AND(H10="Achat",J10="Discount"),AND(H10="Vente",J10="Premium"))*1+AND(K10<>"",K10<>"Aucune")*1+OR(L10="CHoCH",L10="BOS")*1+(M10="Oui")*1+OR(G10="Londres",G10="New York")*1+(O10="Non")*1) | Q10: =IF(P10="","",IF(P10=7,"A+",IF(P10>=5,"B","C"))) | T10: =IF(OR(R10="",S10=""),"",R10+(R10-S10)*Paramètres!$B$6) | V10: =IF(OR(R10="",S10=""),"",ABS(R10-S10)) | W10: =IF(OR(U10="",V10="",N(V10)=0),"",ABS(U10-R10)/V10) | AA10: =IF(Y10="","",IF(Y10="Stop",-1,IF(Y10="BE",0,IF(Y10="TP1 + BE",Paramètres!$B$7*Paramètres!$B$6,IF(Y10="TP1 (100 %)",Paramètres!$B$6,IF(Y10="TP2",Paramètres!$B$7*Paramètres!$B$6+(1-Paramètres!$B$7)*N(W10),IF(Y10="Sortie manuelle",N(Z10),""))))))) | AB10: =IF(AA10="","",AA10*IF(X10="",Paramètres!$B$5,X10)) | AC10: =IF(AB10="","",Paramètres!$B$4*(1+SUM(AB$5:AB10))) | AI10: =IF(AA10="","",SUM(AA$5:AA10)) | AJ10: =IF(AI10="","",MAX(AI10,MAX(AJ$5:AJ9),0)) | AK10: =IF(AI10="","",AI10-AJ10) | AL10: =IF(AA10="","",IF(AA10<0,N(AL9)+1,0)) | AM10: =IF(B10="","",B10-WEEKDAY(B10,2)+1)
A11: =IF(B11="","",ROW()-4) | C11: =IF(B11="","",CHOOSE(WEEKDAY(B11,2),"Lundi","Mardi","Mercredi","Jeudi","Vendredi","Samedi","Dimanche")) | P11: =IF(B11="","",OR(AND(H11="Achat",I11="Haussier"),AND(H11="Vente",I11="Baissier"))*1+OR(AND(H11="Achat",J11="Discount"),AND(H11="Vente",J11="Premium"))*1+AND(K11<>"",K11<>"Aucune")*1+OR(L11="CHoCH",L11="BOS")*1+(M11="Oui")*1+OR(G11="Londres",G11="New York")*1+(O11="Non")*1) | Q11: =IF(P11="","",IF(P11=7,"A+",IF(P11>=5,"B","C"))) | T11: =IF(OR(R11="",S11=""),"",R11+(R11-S11)*Paramètres!$B$6) | V11: =IF(OR(R11="",S11=""),"",ABS(R11-S11)) | W11: =IF(OR(U11="",V11="",N(V11)=0),"",ABS(U11-R11)/V11) | AA11: =IF(Y11="","",IF(Y11="Stop",-1,IF(Y11="BE",0,IF(Y11="TP1 + BE",Paramètres!$B$7*Paramètres!$B$6,IF(Y11="TP1 (100 %)",Paramètres!$B$6,IF(Y11="TP2",Paramètres!$B$7*Paramètres!$B$6+(1-Paramètres!$B$7)*N(W11),IF(Y11="Sortie manuelle",N(Z11),""))))))) | AB11: =IF(AA11="","",AA11*IF(X11="",Paramètres!$B$5,X11)) | AC11: =IF(AB11="","",Paramètres!$B$4*(1+SUM(AB$5:AB11))) | AI11: =IF(AA11="","",SUM(AA$5:AA11)) | AJ11: =IF(AI11="","",MAX(AI11,MAX(AJ$5:AJ10),0)) | AK11: =IF(AI11="","",AI11-AJ11) | AL11: =IF(AA11="","",IF(AA11<0,N(AL10)+1,0)) | AM11: =IF(B11="","",B11-WEEKDAY(B11,2)+1)
A12: =IF(B12="","",ROW()-4) | C12: =IF(B12="","",CHOOSE(WEEKDAY(B12,2),"Lundi","Mardi","Mercredi","Jeudi","Vendredi","Samedi","Dimanche")) | P12: =IF(B12="","",OR(AND(H12="Achat",I12="Haussier"),AND(H12="Vente",I12="Baissier"))*1+OR(AND(H12="Achat",J12="Discount"),AND(H12="Vente",J12="Premium"))*1+AND(K12<>"",K12<>"Aucune")*1+OR(L12="CHoCH",L12="BOS")*1+(M12="Oui")*1+OR(G12="Londres",G12="New York")*1+(O12="Non")*1) | Q12: =IF(P12="","",IF(P12=7,"A+",IF(P12>=5,"B","C"))) | T12: =IF(OR(R12="",S12=""),"",R12+(R12-S12)*Paramètres!$B$6) | V12: =IF(OR(R12="",S12=""),"",ABS(R12-S12)) | W12: =IF(OR(U12="",V12="",N(V12)=0),"",ABS(U12-R12)/V12) | AA12: =IF(Y12="","",IF(Y12="Stop",-1,IF(Y12="BE",0,IF(Y12="TP1 + BE",Paramètres!$B$7*Paramètres!$B$6,IF(Y12="TP1 (100 %)",Paramètres!$B$6,IF(Y12="TP2",Paramètres!$B$7*Paramètres!$B$6+(1-Paramètres!$B$7)*N(W12),IF(Y12="Sortie manuelle",N(Z12),""))))))) | AB12: =IF(AA12="","",AA12*IF(X12="",Paramètres!$B$5,X12)) | AC12: =IF(AB12="","",Paramètres!$B$4*(1+SUM(AB$5:AB12))) | AI12: =IF(AA12="","",SUM(AA$5:AA12)) | AJ12: =IF(AI12="","",MAX(AI12,MAX(AJ$5:AJ11),0)) | AK12: =IF(AI12="","",AI12-AJ12) | AL12: =IF(AA12="","",IF(AA12<0,N(AL11)+1,0)) | AM12: =IF(B12="","",B12-WEEKDAY(B12,2)+1)
A13: =IF(B13="","",ROW()-4) | C13: =IF(B13="","",CHOOSE(WEEKDAY(B13,2),"Lundi","Mardi","Mercredi","Jeudi","Vendredi","Samedi","Dimanche")) | P13: =IF(B13="","",OR(AND(H13="Achat",I13="Haussier"),AND(H13="Vente",I13="Baissier"))*1+OR(AND(H13="Achat",J13="Discount"),AND(H13="Vente",J13="Premium"))*1+AND(K13<>"",K13<>"Aucune")*1+OR(L13="CHoCH",L13="BOS")*1+(M13="Oui")*1+OR(G13="Londres",G13="New York")*1+(O13="Non")*1) | Q13: =IF(P13="","",IF(P13=7,"A+",IF(P13>=5,"B","C"))) | T13: =IF(OR(R13="",S13=""),"",R13+(R13-S13)*Paramètres!$B$6) | V13: =IF(OR(R13="",S13=""),"",ABS(R13-S13)) | W13: =IF(OR(U13="",V13="",N(V13)=0),"",ABS(U13-R13)/V13) | AA13: =IF(Y13="","",IF(Y13="Stop",-1,IF(Y13="BE",0,IF(Y13="TP1 + BE",Paramètres!$B$7*Paramètres!$B$6,IF(Y13="TP1 (100 %)",Paramètres!$B$6,IF(Y13="TP2",Paramètres!$B$7*Paramètres!$B$6+(1-Paramètres!$B$7)*N(W13),IF(Y13="Sortie manuelle",N(Z13),""))))))) | AB13: =IF(AA13="","",AA13*IF(X13="",Paramètres!$B$5,X13)) | AC13: =IF(AB13="","",Paramètres!$B$4*(1+SUM(AB$5:AB13))) | AI13: =IF(AA13="","",SUM(AA$5:AA13)) | AJ13: =IF(AI13="","",MAX(AI13,MAX(AJ$5:AJ12),0)) | AK13: =IF(AI13="","",AI13-AJ13) | AL13: =IF(AA13="","",IF(AA13<0,N(AL12)+1,0)) | AM13: =IF(B13="","",B13-WEEKDAY(B13,2)+1)
A14: =IF(B14="","",ROW()-4) | C14: =IF(B14="","",CHOOSE(WEEKDAY(B14,2),"Lundi","Mardi","Mercredi","Jeudi","Vendredi","Samedi","Dimanche")) | P14: =IF(B14="","",OR(AND(H14="Achat",I14="Haussier"),AND(H14="Vente",I14="Baissier"))*1+OR(AND(H14="Achat",J14="Discount"),AND(H14="Vente",J14="Premium"))*1+AND(K14<>"",K14<>"Aucune")*1+OR(L14="CHoCH",L14="BOS")*1+(M14="Oui")*1+OR(G14="Londres",G14="New York")*1+(O14="Non")*1) | Q14: =IF(P14="","",IF(P14=7,"A+",IF(P14>=5,"B","C"))) | T14: =IF(OR(R14="",S14=""),"",R14+(R14-S14)*Paramètres!$B$6) | V14: =IF(OR(R14="",S14=""),"",ABS(R14-S14)) | W14: =IF(OR(U14="",V14="",N(V14)=0),"",ABS(U14-R14)/V14) | AA14: =IF(Y14="","",IF(Y14="Stop",-1,IF(Y14="BE",0,IF(Y14="TP1 + BE",Paramètres!$B$7*Paramètres!$B$6,IF(Y14="TP1 (100 %)",Paramètres!$B$6,IF(Y14="TP2",Paramètres!$B$7*Paramètres!$B$6+(1-Paramètres!$B$7)*N(W14),IF(Y14="Sortie manuelle",N(Z14),""))))))) | AB14: =IF(AA14="","",AA14*IF(X14="",Paramètres!$B$5,X14)) | AC14: =IF(AB14="","",Paramètres!$B$4*(1+SUM(AB$5:AB14))) | AI14: =IF(AA14="","",SUM(AA$5:AA14)) | AJ14: =IF(AI14="","",MAX(AI14,MAX(AJ$5:AJ13),0)) | AK14: =IF(AI14="","",AI14-AJ14) | AL14: =IF(AA14="","",IF(AA14<0,N(AL13)+1,0)) | AM14: =IF(B14="","",B14-WEEKDAY(B14,2)+1)
A15: =IF(B15="","",ROW()-4) | C15: =IF(B15="","",CHOOSE(WEEKDAY(B15,2),"Lundi","Mardi","Mercredi","Jeudi","Vendredi","Samedi","Dimanche")) | P15: =IF(B15="","",OR(AND(H15="Achat",I15="Haussier"),AND(H15="Vente",I15="Baissier"))*1+OR(AND(H15="Achat",J15="Discount"),AND(H15="Vente",J15="Premium"))*1+AND(K15<>"",K15<>"Aucune")*1+OR(L15="CHoCH",L15="BOS")*1+(M15="Oui")*1+OR(G15="Londres",G15="New York")*1+(O15="Non")*1) | Q15: =IF(P15="","",IF(P15=7,"A+",IF(P15>=5,"B","C"))) | T15: =IF(OR(R15="",S15=""),"",R15+(R15-S15)*Paramètres!$B$6) | V15: =IF(OR(R15="",S15=""),"",ABS(R15-S15)) | W15: =IF(OR(U15="",V15="",N(V15)=0),"",ABS(U15-R15)/V15) | AA15: =IF(Y15="","",IF(Y15="Stop",-1,IF(Y15="BE",0,IF(Y15="TP1 + BE",Paramètres!$B$7*Paramètres!$B$6,IF(Y15="TP1 (100 %)",Paramètres!$B$6,IF(Y15="TP2",Paramètres!$B$7*Paramètres!$B$6+(1-Paramètres!$B$7)*N(W15),IF(Y15="Sortie manuelle",N(Z15),""))))))) | AB15: =IF(AA15="","",AA15*IF(X15="",Paramètres!$B$5,X15)) | AC15: =IF(AB15="","",Paramètres!$B$4*(1+SUM(AB$5:AB15))) | AI15: =IF(AA15="","",SUM(AA$5:AA15)) | AJ15: =IF(AI15="","",MAX(AI15,MAX(AJ$5:AJ14),0)) | AK15: =IF(AI15="","",AI15-AJ15) | AL15: =IF(AA15="","",IF(AA15<0,N(AL14)+1,0)) | AM15: =IF(B15="","",B15-WEEKDAY(B15,2)+1)
A16: =IF(B16="","",ROW()-4) | C16: =IF(B16="","",CHOOSE(WEEKDAY(B16,2),"Lundi","Mardi","Mercredi","Jeudi","Vendredi","Samedi","Dimanche")) | P16: =IF(B16="","",OR(AND(H16="Achat",I16="Haussier"),AND(H16="Vente",I16="Baissier"))*1+OR(AND(H16="Achat",J16="Discount"),AND(H16="Vente",J16="Premium"))*1+AND(K16<>"",K16<>"Aucune")*1+OR(L16="CHoCH",L16="BOS")*1+(M16="Oui")*1+OR(G16="Londres",G16="New York")*1+(O16="Non")*1) | Q16: =IF(P16="","",IF(P16=7,"A+",IF(P16>=5,"B","C"))) | T16: =IF(OR(R16="",S16=""),"",R16+(R16-S16)*Paramètres!$B$6) | V16: =IF(OR(R16="",S16=""),"",ABS(R16-S16)) | W16: =IF(OR(U16="",V16="",N(V16)=0),"",ABS(U16-R16)/V16) | AA16: =IF(Y16="","",IF(Y16="Stop",-1,IF(Y16="BE",0,IF(Y16="TP1 + BE",Paramètres!$B$7*Paramètres!$B$6,IF(Y16="TP1 (100 %)",Paramètres!$B$6,IF(Y16="TP2",Paramètres!$B$7*Paramètres!$B$6+(1-Paramètres!$B$7)*N(W16),IF(Y16="Sortie manuelle",N(Z16),""))))))) | AB16: =IF(AA16="","",AA16*IF(X16="",Paramètres!$B$5,X16)) | AC16: =IF(AB16="","",Paramètres!$B$4*(1+SUM(AB$5:AB16))) | AI16: =IF(AA16="","",SUM(AA$5:AA16)) | AJ16: =IF(AI16="","",MAX(AI16,MAX(AJ$5:AJ15),0)) | AK16: =IF(AI16="","",AI16-AJ16) | AL16: =IF(AA16="","",IF(AA16<0,N(AL15)+1,0)) | AM16: =IF(B16="","",B16-WEEKDAY(B16,2)+1)
A17: =IF(B17="","",ROW()-4) | C17: =IF(B17="","",CHOOSE(WEEKDAY(B17,2),"Lundi","Mardi","Mercredi","Jeudi","Vendredi","Samedi","Dimanche")) | P17: =IF(B17="","",OR(AND(H17="Achat",I17="Haussier"),AND(H17="Vente",I17="Baissier"))*1+OR(AND(H17="Achat",J17="Discount"),AND(H17="Vente",J17="Premium"))*1+AND(K17<>"",K17<>"Aucune")*1+OR(L17="CHoCH",L17="BOS")*1+(M17="Oui")*1+OR(G17="Londres",G17="New York")*1+(O17="Non")*1) | Q17: =IF(P17="","",IF(P17=7,"A+",IF(P17>=5,"B","C"))) | T17: =IF(OR(R17="",S17=""),"",R17+(R17-S17)*Paramètres!$B$6) | V17: =IF(OR(R17="",S17=""),"",ABS(R17-S17)) | W17: =IF(OR(U17="",V17="",N(V17)=0),"",ABS(U17-R17)/V17) | AA17: =IF(Y17="","",IF(Y17="Stop",-1,IF(Y17="BE",0,IF(Y17="TP1 + BE",Paramètres!$B$7*Paramètres!$B$6,IF(Y17="TP1 (100 %)",Paramètres!$B$6,IF(Y17="TP2",Paramètres!$B$7*Paramètres!$B$6+(1-Paramètres!$B$7)*N(W17),IF(Y17="Sortie manuelle",N(Z17),""))))))) | AB17: =IF(AA17="","",AA17*IF(X17="",Paramètres!$B$5,X17)) | AC17: =IF(AB17="","",Paramètres!$B$4*(1+SUM(AB$5:AB17))) | AI17: =IF(AA17="","",SUM(AA$5:AA17)) | AJ17: =IF(AI17="","",MAX(AI17,MAX(AJ$5:AJ16),0)) | AK17: =IF(AI17="","",AI17-AJ17) | AL17: =IF(AA17="","",IF(AA17<0,N(AL16)+1,0)) | AM17: =IF(B17="","",B17-WEEKDAY(B17,2)+1)
... A304: =IF(B304="","",ROW()-4) | C304: =IF(B304="","",CHOOSE(WEEKDAY(B304,2),"Lundi","Mardi","Mercredi","Jeudi","Vendredi","Samedi","Dimanche")) | P304: =IF(B304="","",OR(AND(H304="Achat",I304="Haussier"),AND(H304="Vente",I304="Baissier"))*1+OR(AND(H304="Achat",J304="Discount"),AND(H304="Vente",J304="Premium"))*1+AND(K304<>"",K304<>"Aucune")*1+OR(L304="CHoCH",L304="BOS")*1+(M304="Oui")*1+OR(G304="Londres",G304="New York")*1+(O304="Non")*1) | Q304: =IF(P304="","",IF(P304=7,"A+",IF(P304>=5,"B","C"))) | T304: =IF(OR(R304="",S304=""),"",R304+(R304-S304)*Paramètres!$B$6) | V304: =IF(OR(R304="",S304=""),"",ABS(R304-S304)) | W304: =IF(OR(U304="",V304="",N(V304)=0),"",ABS(U304-R304)/V304) | AA304: =IF(Y304="","",IF(Y304="Stop",-1,IF(Y304="BE",0,IF(Y304="TP1 + BE",Paramètres!$B$7*Paramètres!$B$6,IF(Y304="TP1 (100 %)",Paramètres!$B$6,IF(Y304="TP2",Paramètres!$B$7*Paramètres!$B$6+(1-Paramètres!$B$7)*N(W304),IF(Y304="Sortie manuelle",N(Z304),""))))))) | AB304: =IF(AA304="","",AA304*IF(X304="",Paramètres!$B$5,X304)) | AC304: =IF(AB304="","",Paramètres!$B$4*(1+SUM(AB$5:AB304))) | AI304: =IF(AA304="","",SUM(AA$5:AA304)) | AJ304: =IF(AI304="","",MAX(AI304,MAX(AJ$5:AJ303),0)) | AK304: =IF(AI304="","",AI304-AJ304) | AL304: =IF(AA304="","",IF(AA304<0,N(AL303)+1,0)) | AM304: =IF(B304="","",B304-WEEKDAY(B304,2)+1)

Sheet Tableau de bord
A1: Tableau de bord — Koss Smart Pro
A2: Tout est calculé à partir de la feuille Journal. Ne rien saisir ici.
A4: Indicateur | B4: Valeur | C4: Objectif | D4: Statut
A5: Trades clôturés | B5: =COUNTIF(Journal!$AA$5:$AA$304,">=-100") -> 0
A6: Taux de réussite (R > 0) | B6: =IFERROR(COUNTIF(Journal!$AA$5:$AA$304,">0")/B5,0) -> 0
A7: Taux de TP1 atteint | B7: =IFERROR((COUNTIF(Journal!$Y$5:$Y$304,"TP2")+COUNTIF(Journal!$Y$5:$Y$304,"TP1 + BE")+COUNTIF(Journal!$Y$5:$Y$304,"TP1 (100 %)"))/B5,0) -> 0 | C7: =Paramètres!B8 -> 0.7 | D7: =IF(B5<30,"Échantillon trop petit (< 30 trades)",IF(B7>=C7,"✔ Objectif atteint","✘ Pas encore")) -> Échantillon trop petit (< 30 trades)
A8: Taux de TP2 atteint | B8: =IFERROR(COUNTIF(Journal!$Y$5:$Y$304,"TP2")/B5,0) -> 0
A9: Espérance (R par trade) | B9: =IFERROR(AVERAGE(Journal!$AA$5:$AA$304),0) -> 0 | C9: =Paramètres!B9 -> 0.2 | D9: =IF(B5<30,"Échantillon trop petit (< 30 trades)",IF(B9>=C9,"✔ Stratégie rentable","✘ Espérance insuffisante")) -> Échantillon trop petit (< 30 trades)
A10: Résultat total (R) | B10: =SUM(Journal!$AA$5:$AA$304) -> 0
A11: Gain moyen (R) | B11: =IFERROR(AVERAGEIF(Journal!$AA$5:$AA$304,">0"),0) -> 0
A12: Perte moyenne (R) | B12: =IFERROR(AVERAGEIF(Journal!$AA$5:$AA$304,"<0"),0) -> 0
A13: Profit factor | B13: =IFERROR(SUMIF(Journal!$AA$5:$AA$304,">0")/-SUMIF(Journal!$AA$5:$AA$304,"<0"),0) -> 0 | C13: 1.3 | D13: =IF(B5<30,"Échantillon trop petit (< 30 trades)",IF(B13>=C13,"✔ Bon","✘ À améliorer")) -> Échantillon trop petit (< 30 trades)
A14: Drawdown maximal (R) | B14: =MIN(0,MIN(Journal!$AK$5:$AK$304)) -> 0
A15: Pire série de pertes | B15: =MAX(0,MAX(Journal!$AL$5:$AL$304)) -> 0
A16: Capital actuel ($) | B16: =Paramètres!B4*(1+SUM(Journal!$AB$5:$AB$304)) -> 1000
A17: Performance du compte | B17: =SUM(Journal!$AB$5:$AB$304) -> 0
A18: Discipline (règles respectées) | B18: =IFERROR(COUNTIF(Journal!$AD$5:$AD$304,"Oui")/(COUNTIF(Journal!$AD$5:$AD$304,"Oui")+COUNTIF(Journal!$AD$5:$AD$304,"Non")),0) -> 0 | C18: =Paramètres!B13 -> 0.9 | D18: =IF(COUNTIF(Journal!$AD$5:$AD$304,"Oui")+COUNTIF(Journal!$AD$5:$AD$304,"Non")=0,"–",IF(B18>=C18,"✔ Discipliné","✘ Revoir la discipline")) -> –
A19: Part des setups A+ | B19: =IFERROR(COUNTIFS(Journal!$Q$5:$Q$304,"A+",Journal!$AA$5:$AA$304,">=-100")/B5,0) -> 0
A21: Lecture : un taux de TP1 de 70 % n'a de valeur que si l'espérance est positive. Moins de 30 trades = hasard possible : ne concluez rien avant.
A23: Par qualité de setup (A+ = 7/7)
A24: Catégorie | B24: Trades | C24: Réussite (R > 0) | D24: TP1 atteint | E24: Espérance (R) | F24: Total (R)
A25: =Paramètres!Q4 -> A+ | B25: =COUNTIFS(Journal!$Q$5:$Q$304,$A25,Journal!$AA$5:$AA$304,">=-100") -> 0 | C25: =IF(B25=0,"",COUNTIFS(Journal!$Q$5:$Q$304,$A25,Journal!$AA$5:$AA$304,">0")/B25) | D25: =IF(B25=0,"",(COUNTIFS(Journal!$Q$5:$Q$304,$A25,Journal!$Y$5:$Y$304,"TP2")+COUNTIFS(Journal!$Q$5:$Q$304,$A25,Journal!$Y$5:$Y$304,"TP1 + BE")+COUNTIFS(Journal!$Q$5:$Q$304,$A25,Journal!$Y$5:$Y$304,"TP1 (100 %)"))/B25) | E25: =IF(B25=0,"",F25/B25) | F25: =SUMIFS(Journal!$AA$5:$AA$304,Journal!$Q$5:$Q$304,$A25) -> 0
A26: =Paramètres!Q5 -> B | B26: =COUNTIFS(Journal!$Q$5:$Q$304,$A26,Journal!$AA$5:$AA$304,">=-100") -> 0 | C26: =IF(B26=0,"",COUNTIFS(Journal!$Q$5:$Q$304,$A26,Journal!$AA$5:$AA$304,">0")/B26) | D26: =IF(B26=0,"",(COUNTIFS(Journal!$Q$5:$Q$304,$A26,Journal!$Y$5:$Y$304,"TP2")+COUNTIFS(Journal!$Q$5:$Q$304,$A26,Journal!$Y$5:$Y$304,"TP1 + BE")+COUNTIFS(Journal!$Q$5:$Q$304,$A26,Journal!$Y$5:$Y$304,"TP1 (100 %)"))/B26) | E26: =IF(B26=0,"",F26/B26) | F26: =SUMIFS(Journal!$AA$5:$AA$304,Journal!$Q$5:$Q$304,$A26) -> 0
A27: =Paramètres!Q6 -> C | B27: =COUNTIFS(Journal!$Q$5:$Q$304,$A27,Journal!$AA$5:$AA$304,">=-100") -> 0 | C27: =IF(B27=0,"",COUNTIFS(Journal!$Q$5:$Q$304,$A27,Journal!$AA$5:$AA$304,">0")/B27) | D27: =IF(B27=0,"",(COUNTIFS(Journal!$Q$5:$Q$304,$A27,Journal!$Y$5:$Y$304,"TP2")+COUNTIFS(Journal!$Q$5:$Q$304,$A27,Journal!$Y$5:$Y$304,"TP1 + BE")+COUNTIFS(Journal!$Q$5:$Q$304,$A27,Journal!$Y$5:$Y$304,"TP1 (100 %)"))/B27) | E27: =IF(B27=0,"",F27/B27) | F27: =SUMIFS(Journal!$AA$5:$AA$304,Journal!$Q$5:$Q$304,$A27) -> 0
A29: Par session
A30: Catégorie | B30: Trades | C30: Réussite (R > 0) | D30: TP1 atteint | E30: Espérance (R) | F30: Total (R)
A31: =Paramètres!F4 -> Londres | B31: =COUNTIFS(Journal!$G$5:$G$304,$A31,Journal!$AA$5:$AA$304,">=-100") -> 0 | C31: =IF(B31=0,"",COUNTIFS(Journal!$G$5:$G$304,$A31,Journal!$AA$5:$AA$304,">0")/B31) | D31: =IF(B31=0,"",(COUNTIFS(Journal!$G$5:$G$304,$A31,Journal!$Y$5:$Y$304,"TP2")+COUNTIFS(Journal!$G$5:$G$304,$A31,Journal!$Y$5:$Y$304,"TP1 + BE")+COUNTIFS(Journal!$G$5:$G$304,$A31,Journal!$Y$5:$Y$304,"TP1 (100 %)"))/B31) | E31: =IF(B31=0,"",F31/B31) | F31: =SUMIFS(Journal!$AA$5:$AA$304,Journal!$G$5:$G$304,$A31) -> 0
A32: =Paramètres!F5 -> New York | B32: =COUNTIFS(Journal!$G$5:$G$304,$A32,Journal!$AA$5:$AA$304,">=-100") -> 0 | C32: =IF(B32=0,"",COUNTIFS(Journal!$G$5:$G$304,$A32,Journal!$AA$5:$AA$304,">0")/B32) | D32: =IF(B32=0,"",(COUNTIFS(Journal!$G$5:$G$304,$A32,Journal!$Y$5:$Y$304,"TP2")+COUNTIFS(Journal!$G$5:$G$304,$A32,Journal!$Y$5:$Y$304,"TP1 + BE")+COUNTIFS(Journal!$G$5:$G$304,$A32,Journal!$Y$5:$Y$304,"TP1 (100 %)"))/B32) | E32: =IF(B32=0,"",F32/B32) | F32: =SUMIFS(Journal!$AA$5:$AA$304,Journal!$G$5:$G$304,$A32) -> 0
A33: =Paramètres!F6 -> Asie | B33: =COUNTIFS(Journal!$G$5:$G$304,$A33,Journal!$AA$5:$AA$304,">=-100") -> 0 | C33: =IF(B33=0,"",COUNTIFS(Journal!$G$5:$G$304,$A33,Journal!$AA$5:$AA$304,">0")/B33) | D33: =IF(B33=0,"",(COUNTIFS(Journal!$G$5:$G$304,$A33,Journal!$Y$5:$Y$304,"TP2")+COUNTIFS(Journal!$G$5:$G$304,$A33,Journal!$Y$5:$Y$304,"TP1 + BE")+COUNTIFS(Journal!$G$5:$G$304,$A33,Journal!$Y$5:$Y$304,"TP1 (100 %)"))/B33) | E33: =IF(B33=0,"",F33/B33) | F33: =SUMIFS(Journal!$AA$5:$AA$304,Journal!$G$5:$G$304,$A33) -> 0
A34: =Paramètres!F7 -> Hors killzone | B34: =COUNTIFS(Journal!$G$5:$G$304,$A34,Journal!$AA$5:$AA$304,">=-100") -> 0 | C34: =IF(B34=0,"",COUNTIFS(Journal!$G$5:$G$304,$A34,Journal!$AA$5:$AA$304,">0")/B34) | D34: =IF(B34=0,"",(COUNTIFS(Journal!$G$5:$G$304,$A34,Journal!$Y$5:$Y$304,"TP2")+COUNTIFS(Journal!$G$5:$G$304,$A34,Journal!$Y$5:$Y$304,"TP1 + BE")+COUNTIFS(Journal!$G$5:$G$304,$A34,Journal!$Y$5:$Y$304,"TP1 (100 %)"))/B34) | E34: =IF(B34=0,"",F34/B34) | F34: =SUMIFS(Journal!$AA$5:$AA$304,Journal!$G$5:$G$304,$A34) -> 0
A36: Par marché
A37: Catégorie | B37: Trades | C37: Réussite (R > 0) | D37: TP1 atteint | E37: Espérance (R) | F37: Total (R)
A38: =Paramètres!D4 -> XAUUSD | B38: =COUNTIFS(Journal!$E$5:$E$304,$A38,Journal!$AA$5:$AA$304,">=-100") -> 0 | C38: =IF(B38=0,"",COUNTIFS(Journal!$E$5:$E$304,$A38,Journal!$AA$5:$AA$304,">0")/B38) | D38: =IF(B38=0,"",(COUNTIFS(Journal!$E$5:$E$304,$A38,Journal!$Y$5:$Y$304,"TP2")+COUNTIFS(Journal!$E$5:$E$304,$A38,Journal!$Y$5:$Y$304,"TP1 + BE")+COUNTIFS(Journal!$E$5:$E$304,$A38,Journal!$Y$5:$Y$304,"TP1 (100 %)"))/B38) | E38: =IF(B38=0,"",F38/B38) | F38: =SUMIFS(Journal!$AA$5:$AA$304,Journal!$E$5:$E$304,$A38) -> 0
A39: =Paramètres!D5 -> EURUSD | B39: =COUNTIFS(Journal!$E$5:$E$304,$A39,Journal!$AA$5:$AA$304,">=-100") -> 0 | C39: =IF(B39=0,"",COUNTIFS(Journal!$E$5:$E$304,$A39,Journal!$AA$5:$AA$304,">0")/B39) | D39: =IF(B39=0,"",(COUNTIFS(Journal!$E$5:$E$304,$A39,Journal!$Y$5:$Y$304,"TP2")+COUNTIFS(Journal!$E$5:$E$304,$A39,Journal!$Y$5:$Y$304,"TP1 + BE")+COUNTIFS(Journal!$E$5:$E$304,$A39,Journal!$Y$5:$Y$304,"TP1 (100 %)"))/B39) | E39: =IF(B39=0,"",F39/B39) | F39: =SUMIFS(Journal!$AA$5:$AA$304,Journal!$E$5:$E$304,$A39) -> 0
A40: =Paramètres!D6 -> GBPUSD | B40: =COUNTIFS(Journal!$E$5:$E$304,$A40,Journal!$AA$5:$AA$304,">=-100") -> 0 | C40: =IF(B40=0,"",COUNTIFS(Journal!$E$5:$E$304,$A40,Journal!$AA$5:$AA$304,">0")/B40) | D40: =IF(B40=0,"",(COUNTIFS(Journal!$E$5:$E$304,$A40,Journal!$Y$5:$Y$304,"TP2")+COUNTIFS(Journal!$E$5:$E$304,$A40,Journal!$Y$5:$Y$304,"TP1 + BE")+COUNTIFS(Journal!$E$5:$E$304,$A40,Journal!$Y$5:$Y$304,"TP1 (100 %)"))/B40) | E40: =IF(B40=0,"",F40/B40) | F40: =SUMIFS(Journal!$AA$5:$AA$304,Journal!$E$5:$E$304,$A40) -> 0
A41: =Paramètres!D7 -> USDJPY | B41: =COUNTIFS(Journal!$E$5:$E$304,$A41,Journal!$AA$5:$AA$304,">=-100") -> 0 | C41: =IF(B41=0,"",COUNTIFS(Journal!$E$5:$E$304,$A41,Journal!$AA$5:$AA$304,">0")/B41) | D41: =IF(B41=0,"",(COUNTIFS(Journal!$E$5:$E$304,$A41,Journal!$Y$5:$Y$304,"TP2")+COUNTIFS(Journal!$E$5:$E$304,$A41,Journal!$Y$5:$Y$304,"TP1 + BE")+COUNTIFS(Journal!$E$5:$E$304,$A41,Journal!$Y$5:$Y$304,"TP1 (100 %)"))/B41) | E41: =IF(B41=0,"",F41/B41) | F41: =SUMIFS(Journal!$AA$5:$AA$304,Journal!$E$5:$E$304,$A41) -> 0
A42: =Paramètres!D8 -> NAS100 | B42: =COUNTIFS(Journal!$E$5:$E$304,$A42,Journal!$AA$5:$AA$304,">=-100") -> 0 | C42: =IF(B42=0,"",COUNTIFS(Journal!$E$5:$E$304,$A42,Journal!$AA$5:$AA$304,">0")/B42) | D42: =IF(B42=0,"",(COUNTIFS(Journal!$E$5:$E$304,$A42,Journal!$Y$5:$Y$304,"TP2")+COUNTIFS(Journal!$E$5:$E$304,$A42,Journal!$Y$5:$Y$304,"TP1 + BE")+COUNTIFS(Journal!$E$5:$E$304,$A42,Journal!$Y$5:$Y$304,"TP1 (100 %)"))/B42) | E42: =IF(B42=0,"",F42/B42) | F42: =SUMIFS(Journal!$AA$5:$AA$304,Journal!$E$5:$E$304,$A42) -> 0
A43: =Paramètres!D9 -> US30 | B43: =COUNTIFS(Journal!$E$5:$E$304,$A43,Journal!$AA$5:$AA$304,">=-100") -> 0 | C43: =IF(B43=0,"",COUNTIFS(Journal!$E$5:$E$304,$A43,Journal!$AA$5:$AA$304,">0")/B43) | D43: =IF(B43=0,"",(COUNTIFS(Journal!$E$5:$E$304,$A43,Journal!$Y$5:$Y$304,"TP2")+COUNTIFS(Journal!$E$5:$E$304,$A43,Journal!$Y$5:$Y$304,"TP1 + BE")+COUNTIFS(Journal!$E$5:$E$304,$A43,Journal!$Y$5:$Y$304,"TP1 (100 %)"))/B43) | E43: =IF(B43=0,"",F43/B43) | F43: =SUMIFS(Journal!$AA$5:$AA$304,Journal!$E$5:$E$304,$A43) -> 0
A44: =Paramètres!D10 -> Autre | B44: =COUNTIFS(Journal!$E$5:$E$304,$A44,Journal!$AA$5:$AA$304,">=-100") -> 0 | C44: =IF(B44=0,"",COUNTIFS(Journal!$E$5:$E$304,$A44,Journal!$AA$5:$AA$304,">0")/B44) | D44: =IF(B44=0,"",(COUNTIFS(Journal!$E$5:$E$304,$A44,Journal!$Y$5:$Y$304,"TP2")+COUNTIFS(Journal!$E$5:$E$304,$A44,Journal!$Y$5:$Y$304,"TP1 + BE")+COUNTIFS(Journal!$E$5:$E$304,$A44,Journal!$Y$5:$Y$304,"TP1 (100 %)"))/B44) | E44: =IF(B44=0,"",F44/B44) | F44: =SUMIFS(Journal!$AA$5:$AA$304,Journal!$E$5:$E$304,$A44) -> 0
A46: Par liquidité prise
...

Sheet Revue hebdo
A1: Revue hebdomadaire
A2: À faire chaque week-end (20 min). Les chiffres se calculent seuls ; remplissez les colonnes jaunes.
A4: Semaine du | B4: Trades | C4: Réussite | D4: TP1 atteint | E4: Total R | F4: Cumul R | G4: Règles respectées | H4: Meilleur trade (N°) | I4: Erreur n°1 de la semaine | J4: Ce qui a marché | K4: À corriger | L4: Objectif semaine suivante
A5: =Paramètres!$B$12+7*0 -> 46293 | B5: =COUNTIFS(Journal!$AM$5:$AM$304,$A5,Journal!$AA$5:$AA$304,">=-100") -> 0 | C5: =IF(B5=0,"",COUNTIFS(Journal!$AM$5:$AM$304,$A5,Journal!$AA$5:$AA$304,">0")/B5) | D5: =IF(B5=0,"",(COUNTIFS(Journal!$AM$5:$AM$304,$A5,Journal!$Y$5:$Y$304,"TP2")+COUNTIFS(Journal!$AM$5:$AM$304,$A5,Journal!$Y$5:$Y$304,"TP1 + BE")+COUNTIFS(Journal!$AM$5:$AM$304,$A5,Journal!$Y$5:$Y$304,"TP1 (100 %)"))/B5) | E5: =SUMIFS(Journal!$AA$5:$AA$304,Journal!$AM$5:$AM$304,$A5) -> 0 | F5: =SUM($E$5:E5) -> 0 | G5: =IF(COUNTIFS(Journal!$AM$5:$AM$304,$A5,Journal!$AD$5:$AD$304,"Oui")+COUNTIFS(Journal!$AM$5:$AM$304,$A5,Journal!$AD$5:$AD$304,"Non")=0,"",COUNTIFS(Journal!$AM$5:$AM$304,$A5,Journal!$AD$5:$AD$304,"Oui")/(COUNTIFS(Journal!$AM$5:$AM$304,$A5,Journal!$AD$5:$AD$304,"Oui")+COUNTIFS(Journal!$AM$5:$AM$304,$A5,Journal!$AD$5:$AD$304,"Non")))
A6: =Paramètres!$B$12+7*1 -> 46300 | B6: =COUNTIFS(Journal!$AM$5:$AM$304,$A6,Journal!$AA$5:$AA$304,">=-100") -> 0 | C6: =IF(B6=0,"",COUNTIFS(Journal!$AM$5:$AM$304,$A6,Journal!$AA$5:$AA$304,">0")/B6) | D6: =IF(B6=0,"",(COUNTIFS(Journal!$AM$5:$AM$304,$A6,Journal!$Y$5:$Y$304,"TP2")+COUNTIFS(Journal!$AM$5:$AM$304,$A6,Journal!$Y$5:$Y$304,"TP1 + BE")+COUNTIFS(Journal!$AM$5:$AM$304,$A6,Journal!$Y$5:$Y$304,"TP1 (100 %)"))/B6) | E6: =SUMIFS(Journal!$AA$5:$AA$304,Journal!$AM$5:$AM$304,$A6) -> 0 | F6: =SUM($E$5:E6) -> 0 | G6: =IF(COUNTIFS(Journal!$AM$5:$AM$304,$A6,Journal!$AD$5:$AD$304,"Oui")+COUNTIFS(Journal!$AM$5:$AM$304,$A6,Journal!$AD$5:$AD$304,"Non")=0,"",COUNTIFS(Journal!$AM$5:$AM$304,$A6,Journal!$AD$5:$AD$304,"Oui")/(COUNTIFS(Journal!$AM$5:$AM$304,$A6,Journal!$AD$5:$AD$304,"Oui")+COUNTIFS(Journal!$AM$5:$AM$304,$A6,Journal!$AD$5:$AD$304,"Non")))
A7: =Paramètres!$B$12+7*2 -> 46307 | B7: =COUNTIFS(Journal!$AM$5:$AM$304,$A7,Journal!$AA$5:$AA$304,">=-100") -> 0 | C7: =IF(B7=0,"",COUNTIFS(Journal!$AM$5:$AM$304,$A7,Journal!$AA$5:$AA$304,">0")/B7) | D7: =IF(B7=0,"",(COUNTIFS(Journal!$AM$5:$AM$304,$A7,Journal!$Y$5:$Y$304,"TP2")+COUNTIFS(Journal!$AM$5:$AM$304,$A7,Journal!$Y$5:$Y$304,"TP1 + BE")+COUNTIFS(Journal!$AM$5:$AM$304,$A7,Journal!$Y$5:$Y$304,"TP1 (100 %)"))/B7) | E7: =SUMIFS(Journal!$AA$5:$AA$304,Journal!$AM$5:$AM$304,$A7) -> 0 | F7: =SUM($E$5:E7) -> 0 | G7: =IF(COUNTIFS(Journal!$AM$5:$AM$304,$A7,Journal!$AD$5:$AD$304,"Oui")+COUNTIFS(Journal!$AM$5:$AM$304,$A7,Journal!$AD$5:$AD$304,"Non")=0,"",COUNTIFS(Journal!$AM$5:$AM$304,$A7,Journal!$AD$5:$AD$304,"Oui")/(COUNTIFS(Journal!$AM$5:$AM$304,$A7,Journal!$AD$5:$AD$304,"Oui")+COUNTIFS(Journal!$AM$5:$AM$304,$A7,Journal!$AD$5:$AD$304,"Non")))
A8: =Paramètres!$B$12+7*3 -> 46314 | B8: =COUNTIFS(Journal!$AM$5:$AM$304,$A8,Journal!$AA$5:$AA$304,">=-100") -> 0 | C8: =IF(B8=0,"",COUNTIFS(Journal!$AM$5:$AM$304,$A8,Journal!$AA$5:$AA$304,">0")/B8) | D8: =IF(B8=0,"",(COUNTIFS(Journal!$AM$5:$AM$304,$A8,Journal!$Y$5:$Y$304,"TP2")+COUNTIFS(Journal!$AM$5:$AM$304,$A8,Journal!$Y$5:$Y$304,"TP1 + BE")+COUNTIFS(Journal!$AM$5:$AM$304,$A8,Journal!$Y$5:$Y$304,"TP1 (100 %)"))/B8) | E8: =SUMIFS(Journal!$AA$5:$AA$304,Journal!$AM$5:$AM$304,$A8) -> 0 | F8: =SUM($E$5:E8) -> 0 | G8: =IF(COUNTIFS(Journal!$AM$5:$AM$304,$A8,Journal!$AD$5:$AD$304,"Oui")+COUNTIFS(Journal!$AM$5:$AM$304,$A8,Journal!$AD$5:$AD$304,"Non")=0,"",COUNTIFS(Journal!$AM$5:$AM$304,$A8,Journal!$AD$5:$AD$304,"Oui")/(COUNTIFS(Journal!$AM$5:$AM$304,$A8,Journal!$AD$5:$AD$304,"Oui")+COUNTIFS(Journal!$AM$5:$AM$304,$A8,Journal!$AD$5:$AD$304,"Non")))
A9: =Paramètres!$B$12+7*4 -> 46321 | B9: =COUNTIFS(Journal!$AM$5:$AM$304,$A9,Journal!$AA$5:$AA$304,">=-100") -> 0 | C9: =IF(B9=0,"",COUNTIFS(Journal!$AM$5:$AM$304,$A9,Journal!$AA$5:$AA$304,">0")/B9) | D9: =IF(B9=0,"",(COUNTIFS(Journal!$AM$5:$AM$304,$A9,Journal!$Y$5:$Y$304,"TP2")+COUNTIFS(Journal!$AM$5:$AM$304,$A9,Journal!$Y$5:$Y$304,"TP1 + BE")+COUNTIFS(Journal!$AM$5:$AM$304,$A9,Journal!$Y$5:$Y$304,"TP1 (100 %)"))/B9) | E9: =SUMIFS(Journal!$AA$5:$AA$304,Journal!$AM$5:$AM$304,$A9) -> 0 | F9: =SUM($E$5:E9) -> 0 | G9: =IF(COUNTIFS(Journal!$AM$5:$AM$304,$A9,Journal!$AD$5:$AD$304,"Oui")+COUNTIFS(Journal!$AM$5:$AM$304,$A9,Journal!$AD$5:$AD$304,"Non")=0,"",COUNTIFS(Journal!$AM$5:$AM$304,$A9,Journal!$AD$5:$AD$304,"Oui")/(COUNTIFS(Journal!$AM$5:$AM$304,$A9,Journal!$AD$5:$AD$304,"Oui")+COUNTIFS(Journal!$AM$5:$AM$304,$A9,Journal!$AD$5:$AD$304,"Non")))
A10: =Paramètres!$B$12+7*5 -> 46328 | B10: =COUNTIFS(Journal!$AM$5:$AM$304,$A10,Journal!$AA$5:$AA$304,">=-100") -> 0 | C10: =IF(B10=0,"",COUNTIFS(Journal!$AM$5:$AM$304,$A10,Journal!$AA$5:$AA$304,">0")/B10) | D10: =IF(B10=0,"",(COUNTIFS(Journal!$AM$5:$AM$304,$A10,Journal!$Y$5:$Y$304,"TP2")+COUNTIFS(Journal!$AM$5:$AM$304,$A10,Journal!$Y$5:$Y$304,"TP1 + BE")+COUNTIFS(Journal!$AM$5:$AM$304,$A10,Journal!$Y$5:$Y$304,"TP1 (100 %)"))/B10) | E10: =SUMIFS(Journal!$AA$5:$AA$304,Journal!$AM$5:$AM$304,$A10) -> 0 | F10: =SUM($E$5:E10) -> 0 | G10: =IF(COUNTIFS(Journal!$AM$5:$AM$304,$A10,Journal!$AD$5:$AD$304,"Oui")+COUNTIFS(Journal!$AM$5:$AM$304,$A10,Journal!$AD$5:$AD$304,"Non")=0,"",COUNTIFS(Journal!$AM$5:$AM$304,$A10,Journal!$AD$5:$AD$304,"Oui")/(COUNTIFS(Journal!$AM$5:$AM$304,$A10,Journal!$AD$5:$AD$304,"Oui")+COUNTIFS(Journal!$AM$5:$AM$304,$A10,Journal!$AD$5:$AD$304,"Non")))
A11: =Paramètres!$B$12+7*6 -> 46335 | B11: =COUNTIFS(Journal!$AM$5:$AM$304,$A11,Journal!$AA$5:$AA$304,">=-100") -> 0 | C11: =IF(B11=0,"",COUNTIFS(Journal!$AM$5:$AM$304,$A11,Journal!$AA$5:$AA$304,">0")/B11) | D11: =IF(B11=0,"",(COUNTIFS(Journal!$AM$5:$AM$304,$A11,Journal!$Y$5:$Y$304,"TP2")+COUNTIFS(Journal!$AM$5:$AM$304,$A11,Journal!$Y$5:$Y$304,"TP1 + BE")+COUNTIFS(Journal!$AM$5:$AM$304,$A11,Journal!$Y$5:$Y$304,"TP1 (100 %)"))/B11) | E11: =SUMIFS(Journal!$AA$5:$AA$304,Journal!$AM$5:$AM$304,$A11) -> 0 | F11: =SUM($E$5:E11) -> 0 | G11: =IF(COUNTIFS(Journal!$AM$5:$AM$304,$A11,Journal!$AD$5:$AD$304,"Oui")+COUNTIFS(Journal!$AM$5:$AM$304,$A11,Journal!$AD$5:$AD$304,"Non")=0,"",COUNTIFS(Journal!$AM$5:$AM$304,$A11,Journal!$AD$5:$AD$304,"Oui")/(COUNTIFS(Journal!$AM$5:$AM$304,$A11,Journal!$AD$5:$AD$304,"Oui")+COUNTIFS(Journal!$AM$5:$AM$304,$A11,Journal!$AD$5:$AD$304,"Non")))
A12: =Paramètres!$B$12+7*7 -> 46342 | B12: =COUNTIFS(Journal!$AM$5:$AM$304,$A12,Journal!$AA$5:$AA$304,">=-100") -> 0 | C12: =IF(B12=0,"",COUNTIFS(Journal!$AM$5:$AM$304,$A12,Journal!$AA$5:$AA$304,">0")/B12) | D12: =IF(B12=0,"",(COUNTIFS(Journal!$AM$5:$AM$304,$A12,Journal!$Y$5:$Y$304,"TP2")+COUNTIFS(Journal!$AM$5:$AM$304,$A12,Journal!$Y$5:$Y$304,"TP1 + BE")+COUNTIFS(Journal!$AM$5:$AM$304,$A12,Journal!$Y$5:$Y$304,"TP1 (100 %)"))/B12) | E12: =SUMIFS(Journal!$AA$5:$AA$304,Journal!$AM$5:$AM$304,$A12) -> 0 | F12: =SUM($E$5:E12) -> 0 | G12: =IF(COUNTIFS(Journal!$AM$5:$AM$304,$A12,Journal!$AD$5:$AD$304,"Oui")+COUNTIFS(Journal!$AM$5:$AM$304,$A12,Journal!$AD$5:$AD$304,"Non")=0,"",COUNTIFS(Journal!$AM$5:$AM$304,$A12,Journal!$AD$5:$AD$304,"Oui")/(COUNTIFS(Journal!$AM$5:$AM$304,$A12,Journal!$AD$5:$AD$304,"Oui")+COUNTIFS(Journal!$AM$5:$AM$304,$A12,Journal!$AD$5:$AD$304,"Non")))
A13: =Paramètres!$B$12+7*8 -> 46349 | B13: =COUNTIFS(Journal!$AM$5:$AM$304,$A13,Journal!$AA$5:$AA$304,">=-100") -> 0 | C13: =IF(B13=0,"",COUNTIFS(Journal!$AM$5:$AM$304,$A13,Journal!$AA$5:$AA$304,">0")/B13) | D13: =IF(B13=0,"",(COUNTIFS(Journal!$AM$5:$AM$304,$A13,Journal!$Y$5:$Y$304,"TP2")+COUNTIFS(Journal!$AM$5:$AM$304,$A13,Journal!$Y$5:$Y$304,"TP1 + BE")+COUNTIFS(Journal!$AM$5:$AM$304,$A13,Journal!$Y$5:$Y$304,"TP1 (100 %)"))/B13) | E13: =SUMIFS(Journal!$AA$5:$AA$304,Journal!$AM$5:$AM$304,$A13) -> 0 | F13: =SUM($E$5:E13) -> 0 | G13: =IF(COUNTIFS(Journal!$AM$5:$AM$304,$A13,Journal!$AD$5:$AD$304,"Oui")+COUNTIFS(Journal!$AM$5:$AM$304,$A13,Journal!$AD$5:$AD$304,"Non")=0,"",COUNTIFS(Journal!$AM$5:$AM$304,$A13,Journal!$AD$5:$AD$304,"Oui")/(COUNTIFS(Journal!$AM$5:$AM$304,$A13,Journal!$AD$5:$AD$304,"Oui")+COUNTIFS(Journal!$AM$5:$AM$304,$A13,Journal!$AD$5:$AD$304,"Non")))
A14: =Paramètres!$B$12+7*9 -> 46356 | B14: =COUNTIFS(Journal!$AM$5:$AM$304,$A14,Journal!$AA$5:$AA$304,">=-100") -> 0 | C14: =IF(B14=0,"",COUNTIFS(Journal!$AM$5:$AM$304,$A14,Journal!$AA$5:$AA$304,">0")/B14) | D14: =IF(B14=0,"",(COUNTIFS(Journal!$AM$5:$AM$304,$A14,Journal!$Y$5:$Y$304,"TP2")+COUNTIFS(Journal!$AM$5:$AM$304,$A14,Journal!$Y$5:$Y$304,"TP1 + BE")+COUNTIFS(Journal!$AM$5:$AM$304,$A14,Journal!$Y$5:$Y$304,"TP1 (100 %)"))/B14) | E14: =SUMIFS(Journal!$AA$5:$AA$304,Journal!$AM$5:$AM$304,$A14) -> 0 | F14: =SUM($E$5:E14) -> 0 | G14: =IF(COUNTIFS(Journal!$AM$5:$AM$304,$A14,Journal!$AD$5:$AD$304,"Oui")+COUNTIFS(Journal!$AM$5:$AM$304,$A14,Journal!$AD$5:$AD$304,"Non")=0,"",COUNTIFS(Journal!$AM$5:$AM$304,$A14,Journal!$AD$5:$AD$304,"Oui")/(COUNTIFS(Journal!$AM$5:$AM$304,$A14,Journal!$AD$5:$AD$304,"Oui")+COUNTIFS(Journal!$AM$5:$AM$304,$A14,Journal!$AD$5:$AD$304,"Non")))
A15: =Paramètres!$B$12+7*10 -> 46363 | B15: =COUNTIFS(Journal!$AM$5:$AM$304,$A15,Journal!$AA$5:$AA$304,">=-100") -> 0 | C15: =IF(B15=0,"",COUNTIFS(Journal!$AM$5:$AM$304,$A15,Journal!$AA$5:$AA$304,">0")/B15) | D15: =IF(B15=0,"",(COUNTIFS(Journal!$AM$5:$AM$304,$A15,Journal!$Y$5:$Y$304,"TP2")+COUNTIFS(Journal!$AM$5:$AM$304,$A15,Journal!$Y$5:$Y$304,"TP1 + BE")+COUNTIFS(Journal!$AM$5:$AM$304,$A15,Journal!$Y$5:$Y$304,"TP1 (100 %)"))/B15) | E15: =SUMIFS(Journal!$AA$5:$AA$304,Journal!$AM$5:$AM$304,$A15) -> 0 | F15: =SUM($E$5:E15) -> 0 | G15: =IF(COUNTIFS(Journal!$AM$5:$AM$304,$A15,Journal!$AD$5:$AD$304,"Oui")+COUNTIFS(Journal!$AM$5:$AM$304,$A15,Journal!$AD$5:$AD$304,"Non")=0,"",COUNTIFS(Journal!$AM$5:$AM$304,$A15,Journal!$AD$5:$AD$304,"Oui")/(COUNTIFS(Journal!$AM$5:$AM$304,$A15,Journal!$AD$5:$AD$304,"Oui")+COUNTIFS(Journal!$AM$5:$AM$304,$A15,Journal!$AD$5:$AD$304,"Non")))
A16: =Paramètres!$B$12+7*11 -> 46370 | B16: =COUNTIFS(Journal!$AM$5:$AM$304,$A16,Journal!$AA$5:$AA$304,">=-100") -> 0 | C16: =IF(B16=0,"",COUNTIFS(Journal!$AM$5:$AM$304,$A16,Journal!$AA$5:$AA$304,">0")/B16) | D16: =IF(B16=0,"",(COUNTIFS(Journal!$AM$5:$AM$304,$A16,Journal!$Y$5:$Y$304,"TP2")+COUNTIFS(Journal!$AM$5:$AM$304,$A16,Journal!$Y$5:$Y$304,"TP1 + BE")+COUNTIFS(Journal!$AM$5:$AM$304,$A16,Journal!$Y$5:$Y$304,"TP1 (100 %)"))/B16) | E16: =SUMIFS(Journal!$AA$5:$AA$304,Journal!$AM$5:$AM$304,$A16) -> 0 | F16: =SUM($E$5:E16) -> 0 | G16: =IF(COUNTIFS(Journal!$AM$5:$AM$304,$A16,Journal!$AD$5:$AD$304,"Oui")+COUNTIFS(Journal!$AM$5:$AM$304,$A16,Journal!$AD$5:$AD$304,"Non")=0,"",COUNTIFS(Journal!$AM$5:$AM$304,$A16,Journal!$AD$5:$AD$304,"Oui")/(COUNTIFS(Journal!$AM$5:$AM$304,$A16,Journal!$AD$5:$AD$304,"Oui")+COUNTIFS(Journal!$AM$5:$AM$304,$A16,Journal!$AD$5:$AD$304,"Non")))
A17: =Paramètres!$B$12+7*12 -> 46377 | B17: =COUNTIFS(Journal!$AM$5:$AM$304,$A17,Journal!$AA$5:$AA$304,">=-100") -> 0 | C17: =IF(B17=0,"",COUNTIFS(Journal!$AM$5:$AM$304,$A17,Journal!$AA$5:$AA$304,">0")/B17) | D17: =IF(B17=0,"",(COUNTIFS(Journal!$AM$5:$AM$304,$A17,Journal!$Y$5:$Y$304,"TP2")+COUNTIFS(Journal!$AM$5:$AM$304,$A17,Journal!$Y$5:$Y$304,"TP1 + BE")+COUNTIFS(Journal!$AM$5:$AM$304,$A17,Journal!$Y$5:$Y$304,"TP1 (100 %)"))/B17) | E17: =SUMIFS(Journal!$AA$5:$AA$304,Journal!$AM$5:$AM$304,$A17) -> 0 | F17: =SUM($E$5:E17) -> 0 | G17: =IF(COUNTIFS(Journal!$AM$5:$AM$304,$A17,Journal!$AD$5:$AD$304,"Oui")+COUNTIFS(Journal!$AM$5:$AM$304,$A17,Journal!$AD$5:$AD$304,"Non")=0,"",COUNTIFS(Journal!$AM$5:$AM$304,$A17,Journal!$AD$5:$AD$304,"Oui")/(COUNTIFS(Journal!$AM$5:$AM$304,$A17,Journal!$AD$5:$AD$304,"Oui")+COUNTIFS(Journal!$AM$5:$AM$304,$A17,Journal!$AD$5:$AD$304,"Non")))
A18: =Paramètres!$B$12+7*13 -> 46384 | B18: =COUNTIFS(Journal!$AM$5:$AM$304,$A18,Journal!$AA$5:$AA$304,">=-100") -> 0 | C18: =IF(B18=0,"",COUNTIFS(Journal!$AM$5:$AM$304,$A18,Journal!$AA$5:$AA$304,">0")/B18) | D18: =IF(B18=0,"",(COUNTIFS(Journal!$AM$5:$AM$304,$A18,Journal!$Y$5:$Y$304,"TP2")+COUNTIFS(Journal!$AM$5:$AM$304,$A18,Journal!$Y$5:$Y$304,"TP1 + BE")+COUNTIFS(Journal!$AM$5:$AM$304,$A18,Journal!$Y$5:$Y$304,"TP1 (100 %)"))/B18) | E18: =SUMIFS(Journal!$AA$5:$AA$304,Journal!$AM$5:$AM$304,$A18) -> 0 | F18: =SUM($E$5:E18) -> 0 | G18: =IF(COUNTIFS(Journal!$AM$5:$AM$304,$A18,Journal!$AD$5:$AD$304,"Oui")+COUNTIFS(Journal!$AM$5:$AM$304,$A18,Journal!$AD$5:$AD$304,"Non")=0,"",COUNTIFS(Journal!$AM$5:$AM$304,$A18,Journal!$AD$5:$AD$304,"Oui")/(COUNTIFS(Journal!$AM$5:$AM$304,$A18,Journal!$AD$5:$AD$304,"Oui")+COUNTIFS(Journal!$AM$5:$AM$304,$A18,Journal!$AD$5:$AD$304,"Non")))
A19: =Paramètres!$B$12+7*14 -> 46391 | B19: =COUNTIFS(Journal!$AM$5:$AM$304,$A19,Journal!$AA$5:$AA$304,">=-100") -> 0 | C19: =IF(B19=0,"",COUNTIFS(Journal!$AM$5:$AM$304,$A19,Journal!$AA$5:$AA$304,">0")/B19) | D19: =IF(B19=0,"",(COUNTIFS(Journal!$AM$5:$AM$304,$A19,Journal!$Y$5:$Y$304,"TP2")+COUNTIFS(Journal!$AM$5:$AM$304,$A19,Journal!$Y$5:$Y$304,"TP1 + BE")+COUNTIFS(Journal!$AM$5:$AM$304,$A19,Journal!$Y$5:$Y$304,"TP1 (100 %)"))/B19) | E19: =SUMIFS(Journal!$AA$5:$AA$304,Journal!$AM$5:$AM$304,$A19) -> 0 | F19: =SUM($E$5:E19) -> 0 | G19: =IF(COUNTIFS(Journal!$AM$5:$AM$304,$A19,Journal!$AD$5:$AD$304,"Oui")+COUNTIFS(Journal!$AM$5:$AM$304,$A19,Journal!$AD$5:$AD$304,"Non")=0,"",COUNTIFS(Journal!$AM$5:$AM$304,$A19,Journal!$AD$5:$AD$304,"Oui")/(COUNTIFS(Journal!$AM$5:$AM$304,$A19,Journal!$AD$5:$AD$304,"Oui")+COUNTIFS(Journal!$AM$5:$AM$304,$A19,Journal!$AD$5:$AD$304,"Non")))
A20: =Paramètres!$B$12+7*15 -> 46398 | B20: =COUNTIFS(Journal!$AM$5:$AM$304,$A20,Journal!$AA$5:$AA$304,">=-100") -> 0 | C20: =IF(B20=0,"",COUNTIFS(Journal!$AM$5:$AM$304,$A20,Journal!$AA$5:$AA$304,">0")/B20) | D20: =IF(B20=0,"",(COUNTIFS(Journal!$AM$5:$AM$304,$A20,Journal!$Y$5:$Y$304,"TP2")+COUNTIFS(Journal!$AM$5:$AM$304,$A20,Journal!$Y$5:$Y$304,"TP1 + BE")+COUNTIFS(Journal!$AM$5:$AM$304,$A20,Journal!$Y$5:$Y$304,"TP1 (100 %)"))/B20) | E20: =SUMIFS(Journal!$AA$5:$AA$304,Journal!$AM$5:$AM$304,$A20) -> 0 | F20: =SUM($E$5:E20) -> 0 | G20: =IF(COUNTIFS(Journal!$AM$5:$AM$304,$A20,Journal!$AD$5:$AD$304,"Oui")+COUNTIFS(Journal!$AM$5:$AM$304,$A20,Journal!$AD$5:$AD$304,"Non")=0,"",COUNTIFS(Journal!$AM$5:$AM$304,$A20,Journal!$AD$5:$AD$304,"Oui")/(COUNTIFS(Journal!$AM$5:$AM$304,$A20,Journal!$AD$5:$AD$304,"Oui")+COUNTIFS(Journal!$AM$5:$AM$304,$A20,Journal!$AD$5:$AD$304,"Non")))
A21: =Paramètres!$B$12+7*16 -> 46405 | B21: =COUNTIFS(Journal!$AM$5:$AM$304,$A21,Journal!$AA$5:$AA$304,">=-100") -> 0 | C21: =IF(B21=0,"",COUNTIFS(Journal!$AM$5:$AM$304,$A21,Journal!$AA$5:$AA$304,">0")/B21) | D21: =IF(B21=0,"",(COUNTIFS(Journal!$AM$5:$AM$304,$A21,Journal!$Y$5:$Y$304,"TP2")+COUNTIFS(Journal!$AM$5:$AM$304,$A21,Journal!$Y$5:$Y$304,"TP1 + BE")+COUNTIFS(Journal!$AM$5:$AM$304,$A21,Journal!$Y$5:$Y$304,"TP1 (100 %)"))/B21) | E21: =SUMIFS(Journal!$AA$5:$AA$304,Journal!$AM$5:$AM$304,$A21) -> 0 | F21: =SUM($E$5:E21) -> 0 | G21: =IF(COUNTIFS(Journal!$AM$5:$AM$304,$A21,Journal!$AD$5:$AD$304,"Oui")+COUNTIFS(Journal!$AM$5:$AM$304,$A21,Journal!$AD$5:$AD$304,"Non")=0,"",COUNTIFS(Journal!$AM$5:$AM$304,$A21,Journal!$AD$5:$AD$304,"Oui")/(COUNTIFS(Journal!$AM$5:$AM$304,$A21,Journal!$AD$5:$AD$304,"Oui")+COUNTIFS(Journal!$AM$5:$AM$304,$A21,Journal!$AD$5:$AD$304,"Non")))
A22: =Paramètres!$B$12+7*17 -> 46412 | B22: =COUNTIFS(Journal!$AM$5:$AM$304,$A22,Journal!$AA$5:$AA$304,">=-100") -> 0 | C22: =IF(B22=0,"",COUNTIFS(Journal!$AM$5:$AM$304,$A22,Journal!$AA$5:$AA$304,">0")/B22) | D22: =IF(B22=0,"",(COUNTIFS(Journal!$AM$5:$AM$304,$A22,Journal!$Y$5:$Y$304,"TP2")+COUNTIFS(Journal!$AM$5:$AM$304,$A22,Journal!$Y$5:$Y$304,"TP1 + BE")+COUNTIFS(Journal!$AM$5:$AM$304,$A22,Journal!$Y$5:$Y$304,"TP1 (100 %)"))/B22) | E22: =SUMIFS(Journal!$AA$5:$AA$304,Journal!$AM$5:$AM$304,$A22) -> 0 | F22: =SUM($E$5:E22) -> 0 | G22: =IF(COUNTIFS(Journal!$AM$5:$AM$304,$A22,Journal!$AD$5:$AD$304,"Oui")+COUNTIFS(Journal!$AM$5:$AM$304,$A22,Journal!$AD$5:$AD$304,"Non")=0,"",COUNTIFS(Journal!$AM$5:$AM$304,$A22,Journal!$AD$5:$AD$304,"Oui")/(COUNTIFS(Journal!$AM$5:$AM$304,$A22,Journal!$AD$5:$AD$304,"Oui")+COUNTIFS(Journal!$AM$5:$AM$304,$A22,Journal!$AD$5:$AD$304,"Non")))
A23: =Paramètres!$B$12+7*18 -> 46419 | B23: =COUNTIFS(Journal!$AM$5:$AM$304,$A23,Journal!$AA$5:$AA$304,">=-100") -> 0 | C23: =IF(B23=0,"",COUNTIFS(Journal!$AM$5:$AM$304,$A23,Journal!$AA$5:$AA$304,">0")/B23) | D23: =IF(B23=0,"",(COUNTIFS(Journal!$AM$5:$AM$304,$A23,Journal!$Y$5:$Y$304,"TP2")+COUNTIFS(Journal!$AM$5:$AM$304,$A23,Journal!$Y$5:$Y$304,"TP1 + BE")+COUNTIFS(Journal!$AM$5:$AM$304,$A23,Journal!$Y$5:$Y$304,"TP1 (100 %)"))/B23) | E23: =SUMIFS(Journal!$AA$5:$AA$304,Journal!$AM$5:$AM$304,$A23) -> 0 | F23: =SUM($E$5:E23) -> 0 | G23: =IF(COUNTIFS(Journal!$AM$5:$AM$304,$A23,Journal!$AD$5:$AD$304,"Oui")+COUNTIFS(Journal!$AM$5:$AM$304,$A23,Journal!$AD$5:$AD$304,"Non")=0,"",COUNTIFS(Journal!$AM$5:$AM$304,$A23,Journal!$AD$5:$AD$304,"Oui")/(COUNTIFS(Journal!$AM$5:$AM$304,$A23,Journal!$AD$5:$AD$304,"Oui")+COUNTIFS(Journal!$AM$5:$AM$304,$A23,Journal!$AD$5:$AD$304,"Non")))
A24: =Paramètres!$B$12+7*19 -> 46426 | B24: =COUNTIFS(Journal!$AM$5:$AM$304,$A24,Journal!$AA$5:$AA$304,">=-100") -> 0 | C24: =IF(B24=0,"",COUNTIFS(Journal!$AM$5:$AM$304,$A24,Journal!$AA$5:$AA$304,">0")/B24) | D24: =IF(B24=0,"",(COUNTIFS(Journal!$AM$5:$AM$304,$A24,Journal!$Y$5:$Y$304,"TP2")+COUNTIFS(Journal!$AM$5:$AM$304,$A24,Journal!$Y$5:$Y$304,"TP1 + BE")+COUNTIFS(Journal!$AM$5:$AM$304,$A24,Journal!$Y$5:$Y$304,"TP1 (100 %)"))/B24) | E24: =SUMIFS(Journal!$AA$5:$AA$304,Journal!$AM$5:$AM$304,$A24) -> 0 | F24: =SUM($E$5:E24) -> 0 | G24: =IF(COUNTIFS(Journal!$AM$5:$AM$304,$A24,Journal!$AD$5:$AD$304,"Oui")+COUNTIFS(Journal!$AM$5:$AM$304,$A24,Journal!$AD$5:$AD$304,"Non")=0,"",COUNTIFS(Journal!$AM$5:$AM$304,$A24,Journal!$AD$5:$AD$304,"Oui")/(COUNTIFS(Journal!$AM$5:$AM$304,$A24,Journal!$AD$5:$AD$304,"Oui")+COUNTIFS(Journal!$AM$5:$AM$304,$A24,Journal!$AD$5:$AD$304,"Non")))
A25: =Paramètres!$B$12+7*20 -> 46433 | B25: =COUNTIFS(Journal!$AM$5:$AM$304,$A25,Journal!$AA$5:$AA$304,">=-100") -> 0 | C25: =IF(B25=0,"",COUNTIFS(Journal!$AM$5:$AM$304,$A25,Journal!$AA$5:$AA$304,">0")/B25) | D25: =IF(B25=0,"",(COUNTIFS(Journal!$AM$5:$AM$304,$A25,Journal!$Y$5:$Y$304,"TP2")+COUNTIFS(Journal!$AM$5:$AM$304,$A25,Journal!$Y$5:$Y$304,"TP1 + BE")+COUNTIFS(Journal!$AM$5:$AM$304,$A25,Journal!$Y$5:$Y$304,"TP1 (100 %)"))/B25) | E25: =SUMIFS(Journal!$AA$5:$AA$304,Journal!$AM$5:$AM$304,$A25) -> 0 | F25: =SUM($E$5:E25) -> 0 | G25: =IF(COUNTIFS(Journal!$AM$5:$AM$304,$A25,Journal!$AD$5:$AD$304,"Oui")+COUNTIFS(Journal!$AM$5:$AM$304,$A25,Journal!$AD$5:$AD$304,"Non")=0,"",COUNTIFS(Journal!$AM$5:$AM$304,$A25,Journal!$AD$5:$AD$304,"Oui")/(COUNTIFS(Journal!$AM$5:$AM$304,$A25,Journal!$AD$5:$AD$304,"Oui")+COUNTIFS(Journal!$AM$5:$AM$304,$A25,Journal!$AD$5:$AD$304,"Non")))
A26: =Paramètres!$B$12+7*21 -> 46440 | B26: =COUNTIFS(Journal!$AM$5:$AM$304,$A26,Journal!$AA$5:$AA$304,">=-100") -> 0 | C26: =IF(B26=0,"",COUNTIFS(Journal!$AM$5:$AM$304,$A26,Journal!$AA$5:$AA$304,">0")/B26) | D26: =IF(B26=0,"",(COUNTIFS(Journal!$AM$5:$AM$304,$A26,Journal!$Y$5:$Y$304,"TP2")+COUNTIFS(Journal!$AM$5:$AM$304,$A26,Journal!$Y$5:$Y$304,"TP1 + BE")+COUNTIFS(Journal!$AM$5:$AM$304,$A26,Journal!$Y$5:$Y$304,"TP1 (100 %)"))/B26) | E26: =SUMIFS(Journal!$AA$5:$AA$304,Journal!$AM$5:$AM$304,$A26) -> 0 | F26: =SUM($E$5:E26) -> 0 | G26: =IF(COUNTIFS(Journal!$AM$5:$AM$304,$A26,Journal!$AD$5:$AD$304,"Oui")+COUNTIFS(Journal!$AM$5:$AM$304,$A26,Journal!$AD$5:$AD$304,"Non")=0,"",COUNTIFS(Journal!$AM$5:$AM$304,$A26,Journal!$AD$5:$AD$304,"Oui")/(COUNTIFS(Journal!$AM$5:$AM$304,$A26,Journal!$AD$5:$AD$304,"Oui")+COUNTIFS(Journal!$AM$5:$AM$304,$A26,Journal!$AD$5:$AD$304,"Non")))
A27: =Paramètres!$B$12+7*22 -> 46447 | B27: =COUNTIFS(Journal!$AM$5:$AM$304,$A27,Journal!$AA$5:$AA$304,">=-100") -> 0 | C27: =IF(B27=0,"",COUNTIFS(Journal!$AM$5:$AM$304,$A27,Journal!$AA$5:$AA$304,">0")/B27) | D27: =IF(B27=0,"",(COUNTIFS(Journal!$AM$5:$AM$304,$A27,Journal!$Y$5:$Y$304,"TP2")+COUNTIFS(Journal!$AM$5:$AM$304,$A27,Journal!$Y$5:$Y$304,"TP1 + BE")+COUNTIFS(Journal!$AM$5:$AM$304,$A27,Journal!$Y$5:$Y$304,"TP1 (100 %)"))/B27) | E27: =SUMIFS(Journal!$AA$5:$AA$304,Journal!$AM$5:$AM$304,$A27) -> 0 | F27: =SUM($E$5:E27) -> 0 | G27: =IF(COUNTIFS(Journal!$AM$5:$AM$304,$A27,Journal!$AD$5:$AD$304,"Oui")+COUNTIFS(Journal!$AM$5:$AM$304,$A27,Journal!$AD$5:$AD$304,"Non")=0,"",COUNTIFS(Journal!$AM$5:$AM$304,$A27,Journal!$AD$5:$AD$304,"Oui")/(COUNTIFS(Journal!$AM$5:$AM$304,$A27,Journal!$AD$5:$AD$304,"Oui")+COUNTIFS(Journal!$AM$5:$AM$304,$A27,Journal!$AD$5:$AD$304,"Non")))
A28: =Paramètres!$B$12+7*23 -> 46454 | B28: =COUNTIFS(Journal!$AM$5:$AM$304,$A28,Journal!$AA$5:$AA$304,">=-100") -> 0 | C28: =IF(B28=0,"",COUNTIFS(Journal!$AM$5:$AM$304,$A28,Journal!$AA$5:$AA$304,">0")/B28) | D28: =IF(B28=0,"",(COUNTIFS(Journal!$AM$5:$AM$304,$A28,Journal!$Y$5:$Y$304,"TP2")+COUNTIFS(Journal!$AM$5:$AM$304,$A28,Journal!$Y$5:$Y$304,"TP1 + BE")+COUNTIFS(Journal!$AM$5:$AM$304,$A28,Journal!$Y$5:$Y$304,"TP1 (100 %)"))/B28) | E28: =SUMIFS(Journal!$AA$5:$AA$304,Journal!$AM$5:$AM$304,$A28) -> 0 | F28: =SUM($E$5:E28) -> 0 | G28: =IF(COUNTIFS(Journal!$AM$5:$AM$304,$A28,Journal!$AD$5:$AD$304,"Oui")+COUNTIFS(Journal!$AM$5:$AM$304,$A28,Journal!$AD$5:$AD$304,"Non")=0,"",COUNTIFS(Journal!$AM$5:$AM$304,$A28,Journal!$AD$5:$AD$304,"Oui")/(COUNTIFS(Journal!$AM$5:$AM$304,$A28,Journal!$AD$5:$AD$304,"Oui")+COUNTIFS(Journal!$AM$5:$AM$304,$A28,Journal!$AD$5:$AD$304,"Non")))
A29: =Paramètres!$B$12+7*24 -> 46461 | B29: =COUNTIFS(Journal!$AM$5:$AM$304,$A29,Journal!$AA$5:$AA$304,">=-100") -> 0 | C29: =IF(B29=0,"",COUNTIFS(Journal!$AM$5:$AM$304,$A29,Journal!$AA$5:$AA$304,">0")/B29) | D29: =IF(B29=0,"",(COUNTIFS(Journal!$AM$5:$AM$304,$A29,Journal!$Y$5:$Y$304,"TP2")+COUNTIFS(Journal!$AM$5:$AM$304,$A29,Journal!$Y$5:$Y$304,"TP1 + BE")+COUNTIFS(Journal!$AM$5:$AM$304,$A29,Journal!$Y$5:$Y$304,"TP1 (100 %)"))/B29) | E29: =SUMIFS(Journal!$AA$5:$AA$304,Journal!$AM$5:$AM$304,$A29) -> 0 | F29: =SUM($E$5:E29) -> 0 | G29: =IF(COUNTIFS(Journal!$AM$5:$AM$304,$A29,Journal!$AD$5:$AD$304,"Oui")+COUNTIFS(Journal!$AM$5:$AM$304,$A29,Journal!$AD$5:$AD$304,"Non")=0,"",COUNTIFS(Journal!$AM$5:$AM$304,$A29,Journal!$AD$5:$AD$304,"Oui")/(COUNTIFS(Journal!$AM$5:$AM$304,$A29,Journal!$AD$5:$AD$304,"Oui")+COUNTIFS(Journal!$AM$5:$AM$304,$A29,Journal!$AD$5:$AD$304,"Non")))
A30: =Paramètres!$B$12+7*25 -> 46468 | B30: =COUNTIFS(Journal!$AM$5:$AM$304,$A30,Journal!$AA$5:$AA$304,">=-100") -> 0 | C30: =IF(B30=0,"",COUNTIFS(Journal!$AM$5:$AM$304,$A30,Journal!$AA$5:$AA$304,">0")/B30) | D30: =IF(B30=0,"",(COUNTIFS(Journal!$AM$5:$AM$304,$A30,Journal!$Y$5:$Y$304,"TP2")+COUNTIFS(Journal!$AM$5:$AM$304,$A30,Journal!$Y$5:$Y$304,"TP1 + BE")+COUNTIFS(Journal!$AM$5:$AM$304,$A30,Journal!$Y$5:$Y$304,"TP1 (100 %)"))/B30) | E30: =SUMIFS(Journal!$AA$5:$AA$304,Journal!$AM$5:$AM$304,$A30) -> 0 | F30: =SUM($E$5:E30) -> 0 | G30: =IF(COUNTIFS(Journal!$AM$5:$AM$304,$A30,Journal!$AD$5:$AD$304,"Oui")+COUNTIFS(Journal!$AM$5:$AM$304,$A30,Journal!$AD$5:$AD$304,"Non")=0,"",COUNTIFS(Journal!$AM$5:$AM$304,$A30,Journal!$AD$5:$AD$304,"Oui")/(COUNTIFS(Journal!$AM$5:$AM$304,$A30,Journal!$AD$5:$AD$304,"Oui")+COUNTIFS(Journal!$AM$5:$AM$304,$A30,Journal!$AD$5:$AD$304,"Non")))

Sheet Paramètres
A1: Paramètres et listes
A2: Cellules jaunes = à adapter. Les listes (colonnes D à R) alimentent les menus déroulants du journal : vous pouvez en ajouter.
A3: Paramètre | B3: Valeur | C3: Note | D3: Marchés | E3: Timeframes | F3: Sessions | G3: Sens | H3: Biais HTF | I3: Zone de prix | J3: Liquidité prise | K3: MSS | L3: Oui / Non | M3: Zone d'entrée | N3: Résultats | O3: Émotions | P3: Erreurs | Q3: Qualité | R3: Jours
A4: Capital initial du compte ($) | B4: 1000 | C4: Montant de votre compte au début du journal (source : vous). | D4: XAUUSD | E4: M1 | F4: Londres | G4: Achat | H4: Haussier | I4: Discount | J4: PDH | K4: CHoCH | L4: Oui | M4: FVG | N4: TP2 | O4: Calme | P4: Aucune | Q4: A+ | R4: Lundi
A5: Risque par trade par défaut | B5: 0.005 | C5: 0,5 % conseillé au début (stratégie Koss Smart Pro). | D5: EURUSD | E5: M5 | F5: New York | G5: Vente | H5: Baissier | I5: Premium | J5: PDL | K5: BOS | L5: Non | M5: Order Block | N5: TP1 + BE | O5: Confiant | P5: Hors killzone | Q5: B | R5: Mardi
A6: TP1 (en R) | B6: 1 | C6: Objectif 1 = 1 fois le risque (stratégie Koss Smart Pro). | D6: GBPUSD | E6: M15 | F6: Asie | H6: Indéfini | I6: Équilibre | J6: AS H | K6: Aucun | M6: FVG + OB | N6: TP1 (100 %) | O6: Impatient | P6: Sans sweep | Q6: C | R6: Mercredi
A7: Part fermée à TP1 | B7: 0.5 | C7: 50 % fermés à TP1, puis stop au prix d'entrée. | D7: USDJPY | E7: H1 | F7: Hors killzone | J7: AS L | N7: BE | O7: FOMO | P7: Contre le biais | R7: Jeudi
A8: Objectif : taux de TP1 atteint | B8: 0.7 | C8: Votre objectif de 70 %. | D8: NAS100 | J8: EQH | N8: Stop | O8: Peur | P8: Annonce ignorée | R8: Vendredi
A9: Objectif : espérance (R par trade) | B9: 0.2 | C9: Au-dessus de +0,2 R par trade = stratégie rentable et robuste. | D9: US30 | J9: EQL | N9: Sortie manuelle | O9: Revanche | P9: Entrée anticipée
A10: Trades maximum par jour | B10: 2 | C10: Règle de la stratégie. | D10: Autre | J10: BSL | O10: Fatigué | P10: Stop déplacé
A11: Perte maximum par jour (en R) | B11: 2 | C11: Au-delà : arrêt pour la journée. | J11: SSL | P11: Sortie trop tôt
A12: Lundi de la 1re semaine du journal | B12: 46293 | C12: Sert à la feuille « Revue hebdo ». Mettez un LUNDI. | J12: Aucune | P12: Sur-risque
A13: Objectif : règles respectées | B13: 0.9 | C13: Discipline visée. | P13: Revenge trading
